Workbook

Sheet operacje
A1: Kwota | B1: Bank | C1: Produkt | D1: Kategoria | E1: Typ | F1: Data | G1: Miesiąc
A2: -1500 | B2: mBank | C2: Konto | D2: Jedzenie | E2: Wydatki | F2: 45296 | G2: 1
A3: 4500 | B3: mBank | C3: Konto | D3: Wypłata | E3: Wpływy | F3: 45301 | G3: 1
A4: -2000 | B4: mBank | C4: Konto | D4: Mieszkanie | E4: Wydatki | F4: 45302 | G4: 1
A5: -45 | B5: PKO BP | C5: Konto | D5: Jedzenie | E5: Wydatki | F5: 45305 | G5: 1
A6: -150 | B6: mBank | C6: Karta | D6: Subskrypcje | E6: Wydatki | F6: 45306 | G6: 1
A7: -120 | B7: mBank | C7: Konto | D7: Jedzenie | E7: Wydatki | F7: 45307 | G7: 1
A8: 500 | B8: mBank | C8: Konto | D8: Pozostałe wpływy | E8: Wpływy | F8: 45308 | G8: 1
A9: -500 | B9: mBank | C9: Lokata | D9: Pozostałe wydatki | E9: Wydatki | F9: 45308 | G9: 1
A10: 250 | B10: PKO BP | C10: Skarbonka | D10: Kieszonkowe | E10: Wpływy | F10: 45308 | G10: 1
A11: -25 | B11: mBank | C11: Karta | D11: Rozrywka | E11: Wydatki | F11: 45310 | G11: 1
A12: -80 | B12: mBank | C12: Konto | D12: Transport | E12: Wydatki | F12: 45311 | G12: 1
A13: 150 | B13: PKO BP | C13: Konto | D13: Pozostałe wpływy | E13: Wpływy | F13: 45312 | G13: 1
... A207: -300 | B207: Portfel | C207: Gotówka | D207: Jedzenie | E207: Wydatki | F207: 45656 | G207: 12

Sheet dictionary
A1: Category | B1: Type | D1: Bank | E1: Product | H1: Millennium | I1: Santander | J1: Wallet
A2: Accomodation | B2: Expense | D2: Millennium | E2: Account | H2: Account | I2: Account | J2: Gift card
A3: Clothing | B3: Expense | D3: Millennium | E3: Savings account | H3: Savings account | I3: Credit card | J3: Money
A4: Entertainment | B4: Expense | D4: Santander | E4: Account | I4: Fixed-term deposit
A5: Groceries | B5: Expense | D5: Santander | E5: Credit card
A6: Health&Beauty | B6: Expense | D6: Santander | E6: Fixed-term deposit
A7: Multimedia | B7: Expense | D7: Wallet | E7: Gift card
A8: Other expences | B8: Expense | D8: Wallet | E8: Money
A9: Studies | B9: Expense
A10: Transportation | B10: Expense
A11: Allowance | B11: Income
A12: Financial | B12: Income
A13: Gift | B13: Income
A14: Other incoms | B14: Income
A15: Salary | B15: Income
A16: Scholarship | B16: Income
A17: Transfer | B17: Transfer

Sheet operations
A1: Amount | B1: Bank | C1: Product | D1: Category | E1: Type | F1: Date | G1: Month
A2: -1500 | B2: Santander | C2: Account | D2: Groceries | E2: =_xlfn.XLOOKUP(operations[[#This Row],[Category]],categories[Category],categories[Type],"",0,1) -> Expense | F2: 45296 | G2: =MONTH(operations[[#This Row],[Date]]) -> 1 | J2: {=CHOOSE(MATCH(B2,dictionary!$H$1:$J$1,0),_xlfn._TRO_TRAILING(dictionary!$H$2:$H$8),_xlfn._TRO_TRAILING(dictionary!$I$2:$I$8),_xlfn._TRO_TRAILING(dictionary!$J$2:$J$8))} -> Account
A3: 4500 | B3: Santander | C3: Account | D3: Salary | E3: =_xlfn.XLOOKUP(operations[[#This Row],[Category]],categories[Category],categories[Type],"",0,1) -> Income | F3: 45301 | G3: =MONTH(operations[[#This Row],[Date]]) -> 1 | J3: Credit card
A4: -2000 | B4: Santander | C4: Account | D4: Accomodation | E4: =_xlfn.XLOOKUP(operations[[#This Row],[Category]],categories[Category],categories[Type],"",0,1) -> Expense | F4: 45302 | G4: =MONTH(operations[[#This Row],[Date]]) -> 1 | J4: Fixed-term deposit
A5: -45 | B5: Millennium | C5: Account | D5: Groceries | E5: =_xlfn.XLOOKUP(operations[[#This Row],[Category]],categories[Category],categories[Type],"",0,1) -> Expense | F5: 45305 | G5: =MONTH(operations[[#This Row],[Date]]) -> 1
A6: -150 | B6: Santander | C6: Credit card | D6: Multimedia | E6: =_xlfn.XLOOKUP(operations[[#This Row],[Category]],categories[Category],categories[Type],"",0,1) -> Expense | F6: 45306 | G6: =MONTH(operations[[#This Row],[Date]]) -> 1
A7: -120 | B7: Santander | C7: Account | D7: Groceries | E7: =_xlfn.XLOOKUP(operations[[#This Row],[Category]],categories[Category],categories[Type],"",0,1) -> Expense | F7: 45307 | G7: =MONTH(operations[[#This Row],[Date]]) -> 1 | P7: {=CHOOSE(MATCH(B2,dictionary!$H$1:$J$1,0),_xlfn._TRO_TRAILING(dictionary!$H$2:$H$8),_xlfn._TRO_TRAILING(dictionary!$I$2:$I$8),_xlfn._TRO_TRAILING(dictionary!$J$2:$J$8))} -> Account
A8: 500 | B8: Santander | C8: Account | D8: Other incoms | E8: =_xlfn.XLOOKUP(operations[[#This Row],[Category]],categories[Category],categories[Type],"",0,1) -> Income | F8: 45308 | G8: =MONTH(operations[[#This Row],[Date]]) -> 1 | P8: Credit card
A9: -500 | B9: Santander | C9: Fixed-term deposit | D9: Other expences | E9: =_xlfn.XLOOKUP(operations[[#This Row],[Category]],categories[Category],categories[Type],"",0,1) -> Expense | F9: 45308 | G9: =MONTH(operations[[#This Row],[Date]]) -> 1 | P9: Fixed-term deposit
A10: 250 | B10: Millennium | C10: Savings account | D10: Allowance | E10: =_xlfn.XLOOKUP(operations[[#This Row],[Category]],categories[Category],categories[Type],"",0,1) -> Income | F10: 45308 | G10: =MONTH(operations[[#This Row],[Date]]) -> 1
A11: -25 | B11: Santander | C11: Credit card | D11: Entertainment | E11: =_xlfn.XLOOKUP(operations[[#This Row],[Category]],categories[Category],categories[Type],"",0,1) -> Expense | F11: 45310 | G11: =MONTH(operations[[#This Row],[Date]]) -> 1
A12: -80 | B12: Santander | C12: Account | D12: Transportation | E12: =_xlfn.XLOOKUP(operations[[#This Row],[Category]],categories[Category],categories[Type],"",0,1) -> Expense | F12: 45311 | G12: =MONTH(operations[[#This Row],[Date]]) -> 1
A13: 150 | B13: Millennium | C13: Account | D13: Other incoms | E13: =_xlfn.XLOOKUP(operations[[#This Row],[Category]],categories[Category],categories[Type],"",0,1) -> Income | F13: 45312 | G13: =MONTH(operations[[#This Row],[Date]]) -> 1
A14: -80 | B14: Millennium | C14: Account | D14: Clothing | E14: =_xlfn.XLOOKUP(operations[[#This Row],[Category]],categories[Category],categories[Type],"",0,1) -> Expense | F14: 45313 | G14: =MONTH(operations[[#This Row],[Date]]) -> 1
A15: -60 | B15: Millennium | C15: Account | D15: Entertainment | E15: =_xlfn.XLOOKUP(operations[[#This Row],[Category]],categories[Category],categories[Type],"",0,1) -> Expense | F15: 45314 | G15: =MONTH(operations[[#This Row],[Date]]) -> 1
A16: -100 | B16: Santander | C16: Account | D16: Studies | E16: =_xlfn.XLOOKUP(operations[[#This Row],[Category]],categories[Category],categories[Type],"",0,1) -> Expense | F16: 45315 | G16: =MONTH(operations[[#This Row],[Date]]) -> 1
A17: -50 | B17: Wallet | C17: Gift card | D17: Groceries | E17: =_xlfn.XLOOKUP(operations[[#This Row],[Category]],categories[Category],categories[Type],"",0,1) -> Expense | F17: 45316 | G17: =MONTH(operations[[#This Row],[Date]]) -> 1
A18: 150 | B18: Wallet | C18: Money | D18: Other incoms | E18: =_xlfn.XLOOKUP(operations[[#This Row],[Category]],categories[Category],categories[Type],"",0,1) -> Income | F18: 45316 | G18: =MONTH(operations[[#This Row],[Date]]) -> 1
A19: 5.5 | B19: Millennium | C19: Savings account | D19: Financial | E19: =_xlfn.XLOOKUP(operations[[#This Row],[Category]],categories[Category],categories[Type],"",0,1) -> Income | F19: 45317 | G19: =MONTH(operations[[#This Row],[Date]]) -> 1
A20: 100 | B20: Santander | C20: Fixed-term deposit | D20: Financial | E20: =_xlfn.XLOOKUP(operations[[#This Row],[Category]],categories[Category],categories[Type],"",0,1) -> Income | F20: 45318 | G20: =MONTH(operations[[#This Row],[Date]]) -> 1
A21: -100 | B21: Santander | C21: Account | D21: Health&Beauty | E21: =_xlfn.XLOOKUP(operations[[#This Row],[Category]],categories[Category],categories[Type],"",0,1) -> Expense | F21: 45319 | G21: =MONTH(operations[[#This Row],[Date]]) -> 1
... A207: -300 | B207: Wallet | C207: Money | D207: Groceries | E207: =_xlfn.XLOOKUP(operations[[#This Row],[Category]],categories[Category],categories[Type],"",0,1) -> Expense | F207: 45656 | G207: =MONTH(operations[[#This Row],[Date]]) -> 12

Sheet 1
A1: Bank | B1: Product | C1: Opening balance | D1: Operation | E1: Closing balance | G1: Category | H1: Total | J1: Category | K1: Total | N1: Type
A2: Millennium | B2: Account | C2: 100 | D2: =SUMIFS(operations[Amount],operations[Bank],raports_1[[#This Row],[Bank]],operations[Product],raports_1[[#This Row],[Product]],operations[Month],$B$12) -> -35 | E2: =raports_1[[#This Row],[Opening balance]]+raports_1[[#This Row],[Operation]] -> 65 | G2: Accomodation | H2: =SUMIFS(operations[Amount],operations[Category],Expenses[[#This Row],[Category]],operations[Month],'1'!$B$12) -> -2000 | J2: Other expences | K2: =SUMIFS(operations[Amount],operations[Category],Table9[[#This Row],[Category]],operations[Month],'1'!$B$12) -> -500 | N2: Expense
A3: Millennium | B3: Savings account | C3: 10.5 | D3: =SUMIFS(operations[Amount],operations[Bank],raports_1[[#This Row],[Bank]],operations[Product],raports_1[[#This Row],[Product]],operations[Month],$B$12) -> 255.5 | E3: =raports_1[[#This Row],[Opening balance]]+raports_1[[#This Row],[Operation]] -> 266 | G3: Clothing | H3: =SUMIFS(operations[Amount],operations[Category],Expenses[[#This Row],[Category]],operations[Month],'1'!$B$12) -> -80 | J3: Studies | K3: =SUMIFS(operations[Amount],operations[Category],Table9[[#This Row],[Category]],operations[Month],'1'!$B$12) -> -100 | N3: Expense
A4: Santander | B4: Account | C4: 600 | D4: =SUMIFS(operations[Amount],operations[Bank],raports_1[[#This Row],[Bank]],operations[Product],raports_1[[#This Row],[Product]],operations[Month],$B$12) -> 1100 | E4: =raports_1[[#This Row],[Opening balance]]+raports_1[[#This Row],[Operation]] -> 1700 | G4: Entertainment | H4: =SUMIFS(operations[Amount],operations[Category],Expenses[[#This Row],[Category]],operations[Month],'1'!$B$12) -> -85 | J4: Transportation | K4: =SUMIFS(operations[Amount],operations[Category],Table9[[#This Row],[Category]],operations[Month],'1'!$B$12) -> -80 | N4: Expense
A5: Santander | B5: Credit card | C5: 0 | D5: =SUMIFS(operations[Amount],operations[Bank],raports_1[[#This Row],[Bank]],operations[Product],raports_1[[#This Row],[Product]],operations[Month],$B$12) -> -175 | E5: =raports_1[[#This Row],[Opening balance]]+raports_1[[#This Row],[Operation]] -> -175 | G5: Groceries | H5: =SUMIFS(operations[Amount],operations[Category],Expenses[[#This Row],[Category]],operations[Month],'1'!$B$12) -> -1715 | J5: Allowance | K5: =SUMIFS(operations[Amount],operations[Category],Table9[[#This Row],[Category]],operations[Month],'1'!$B$12) -> 250 | N5: Expense
A6: Santander | B6: Fixed-term deposit | C6: 2000 | D6: =SUMIFS(operations[Amount],operations[Bank],raports_1[[#This Row],[Bank]],operations[Product],raports_1[[#This Row],[Product]],operations[Month],$B$12) -> -400 | E6: =raports_1[[#This Row],[Opening balance]]+raports_1[[#This Row],[Operation]] -> 1600 | G6: Health&Beauty | H6: =SUMIFS(operations[Amount],operations[Category],Expenses[[#This Row],[Category]],operations[Month],'1'!$B$12) -> -100 | J6: Financial | K6: =SUMIFS(operations[Amount],operations[Category],Table9[[#This Row],[Category]],operations[Month],'1'!$B$12) -> 105.5 | N6: Expense
A7: Wallet | B7: Gift card | C7: 200 | D7: =SUMIFS(operations[Amount],operations[Bank],raports_1[[#This Row],[Bank]],operations[Product],raports_1[[#This Row],[Product]],operations[Month],$B$12) -> -50 | E7: =raports_1[[#This Row],[Opening balance]]+raports_1[[#This Row],[Operation]] -> 150 | G7: Multimedia | H7: =SUMIFS(operations[Amount],operations[Category],Expenses[[#This Row],[Category]],operations[Month],'1'!$B$12) -> -150 | J7: Gift | K7: =SUMIFS(operations[Amount],operations[Category],Table9[[#This Row],[Category]],operations[Month],'1'!$B$12) -> 0 | N7: Expense
A8: Wallet | B8: Money | C8: 30 | D8: =SUMIFS(operations[Amount],operations[Bank],raports_1[[#This Row],[Bank]],operations[Product],raports_1[[#This Row],[Product]],operations[Month],$B$12) -> 150 | E8: =raports_1[[#This Row],[Opening balance]]+raports_1[[#This Row],[Operation]] -> 180 | G8: Total | H8: =SUBTOTAL(109,Expenses[Total]) -> -4130 | J8: Other incoms | K8: =SUMIFS(operations[Amount],operations[Category],Table9[[#This Row],[Category]],operations[Month],'1'!$B$12) -> 800 | N8: Expense
A9: Total | C9: =SUBTOTAL(109,raports_1[Opening balance]) -> 2940.5 | D9: =SUBTOTAL(109,raports_1[Operation]) -> 845.5 | E9: =SUBTOTAL(109,raports_1[Closing balance]) -> 3786 | J9: Salary | K9: =SUMIFS(operations[Amount],operations[Category],Table9[[#This Row],[Category]],operations[Month],'1'!$B$12) -> 4500 | N9: Expense
J10: Scholarship | K10: =SUMIFS(operations[Amount],operations[Category],Table9[[#This Row],[Category]],operations[Month],'1'!$B$12) -> 0 | N10: Expense
J11: Transfer | K11: =SUMIFS(operations[Amount],operations[Category],Table9[[#This Row],[Category]],operations[Month],'1'!$B$12) -> 0 | N11: Income
A12: Month | B12: {=_xlfn.TEXTAFTER(CELL("filename",A1),"]")} -> 1 | J12: Total | K12: =SUBTOTAL(109,Table9[Total]) -> 4975.5 | N12: Income
N13: Income
A14: Type | B14: Total | N14: Income
A15: Income | B15: =SUMIFS(operations[Amount],operations[Type],balance_1[[#This Row],[Type]],operations[Month],'1'!$B$12) -> 5655.5 | N15: Income
A16: Expense | B16: =SUMIFS(operations[Amount],operations[Type],balance_1[[#This Row],[Type]],operations[Month],'1'!$B$12) -> -4810 | N16: Income
A17: Transfer | B17: =SUMIFS(operations[Amount],operations[Type],balance_1[[#This Row],[Type]],operations[Month],'1'!$B$12) -> 0 | N17: Transfer
A18: Total | B18: =SUBTOTAL(109,balance_1[Total]) -> 845.5

Sheet 2
A1: Bank | B1: Product | C1: Opening balance | D1: Operation | E1: Closing balance | G1: Category | H1: Total | J1: Category | K1: Total | N1: Type
A2: Millennium | B2: Account | C2: {=INDIRECT("raport_"&$B$12-1&"[@[Closing balance ]]")} -> #REF! | D2: =SUMIFS(operations[Amount],operations[Bank],raports_2[[#This Row],[Bank]],operations[Product],raports_2[[#This Row],[Product]],operations[Month],$B$12) -> 35 | E2: =raports_2[[#This Row],[Opening balance]]+raports_2[[#This Row],[Operation]] -> #REF! | G2: Accomodation | H2: =SUMIFS(operations[Amount],operations[Category],Expenses2[[#This Row],[Category]],operations[Month],'1'!$B$12) -> -2000 | J2: Other expences | N2: Expense
A3: Millennium | B3: Savings account | C3: 10.5 | D3: =SUMIFS(operations[Amount],operations[Bank],raports_2[[#This Row],[Bank]],operations[Product],raports_2[[#This Row],[Product]],operations[Month],$B$12) -> 15 | E3: =raports_2[[#This Row],[Opening balance]]+raports_2[[#This Row],[Operation]] -> 25.5 | G3: Clothing | H3: =SUMIFS(operations[Amount],operations[Category],Expenses2[[#This Row],[Category]],operations[Month],'1'!$B$12) -> -80 | J3: Studies | K3: =SUMIFS(operations[Amount],operations[Category],Table916[[#This Row],[Category]],operations[Month],'1'!$B$12) -> -100 | N3: Expense
A4: Santander | B4: Account | C4: 600 | D4: =SUMIFS(operations[Amount],operations[Bank],raports_2[[#This Row],[Bank]],operations[Product],raports_2[[#This Row],[Product]],operations[Month],$B$12) -> 2039.5 | E4: =raports_2[[#This Row],[Opening balance]]+raports_2[[#This Row],[Operation]] -> 2639.5 | G4: Entertainment | H4: =SUMIFS(operations[Amount],operations[Category],Expenses2[[#This Row],[Category]],operations[Month],'1'!$B$12) -> -85 | J4: Transportation | K4: =SUMIFS(operations[Amount],operations[Category],Table916[[#This Row],[Category]],operations[Month],'1'!$B$12) -> -80 | N4: Expense
A5: Santander | B5: Credit card | C5: 0 | D5: =SUMIFS(operations[Amount],operations[Bank],raports_2[[#This Row],[Bank]],operations[Product],raports_2[[#This Row],[Product]],operations[Month],$B$12) -> 175 | E5: =raports_2[[#This Row],[Opening balance]]+raports_2[[#This Row],[Operation]] -> 175 | G5: Groceries | H5: =SUMIFS(operations[Amount],operations[Category],Expenses2[[#This Row],[Category]],operations[Month],'1'!$B$12) -> -1715 | J5: Allowance | K5: =SUMIFS(operations[Amount],operations[Category],Table916[[#This Row],[Category]],operations[Month],'1'!$B$12) -> 250 | N5: Expense
A6: Santander | B6: Fixed-term deposit | C6: 2000 | D6: =SUMIFS(operations[Amount],operations[Bank],raports_2[[#This Row],[Bank]],operations[Product],raports_2[[#This Row],[Product]],operations[Month],$B$12) -> -400 | E6: =raports_2[[#This Row],[Opening balance]]+raports_2[[#This Row],[Operation]] -> 1600 | G6: Health&Beauty | H6: =SUMIFS(operations[Amount],operations[Category],Expenses2[[#This Row],[Category]],operations[Month],'1'!$B$12) -> -100 | J6: Financial | K6: =SUMIFS(operations[Amount],operations[Category],Table916[[#This Row],[Category]],operations[Month],'1'!$B$12) -> 105.5 | N6: Expense
A7: Wallet | B7: Gift card | C7: 200 | D7: =SUMIFS(operations[Amount],operations[Bank],raports_2[[#This Row],[Bank]],operations[Product],raports_2[[#This Row],[Product]],operations[Month],$B$12) -> 100 | E7: =raports_2[[#This Row],[Opening balance]]+raports_2[[#This Row],[Operation]] -> 300 | G7: Multimedia | H7: =SUMIFS(operations[Amount],operations[Category],Expenses2[[#This Row],[Category]],operations[Month],'1'!$B$12) -> -150 | J7: Gift | K7: =SUMIFS(operations[Amount],operations[Category],Table916[[#This Row],[Category]],operations[Month],'1'!$B$12) -> 0 | N7: Expense
A8: Wallet | B8: Money | C8: 30 | D8: =SUMIFS(operations[Amount],operations[Bank],raports_2[[#This Row],[Bank]],operations[Product],raports_2[[#This Row],[Product]],operations[Month],$B$12) -> 500 | E8: =raports_2[[#This Row],[Opening balance]]+raports_2[[#This Row],[Operation]] -> 530 | G8: Total | H8: =SUBTOTAL(109,Expenses2[Total]) -> -4130 | J8: Other incoms | K8: =SUMIFS(operations[Amount],operations[Category],Table916[[#This Row],[Category]],operations[Month],'1'!$B$12) -> 800 | N8: Expense
A9: Total | C9: =SUBTOTAL(109,raports_2[Opening balance]) -> #REF! | D9: =SUBTOTAL(109,raports_2[Operation]) -> 2464.5 | E9: =SUBTOTAL(109,raports_2[Closing balance]) -> #REF! | J9: Salary | K9: =SUMIFS(operations[Amount],operations[Category],Table916[[#This Row],[Category]],operations[Month],'1'!$B$12) -> 4500 | N9: Expense
J10: Scholarship | K10: =SUMIFS(operations[Amount],operations[Category],Table916[[#This Row],[Category]],operations[Month],'1'!$B$12) -> 0 | N10: Expense
J11: Transfer | K11: =SUMIFS(operations[Amount],operations[Category],Table916[[#This Row],[Category]],operations[Month],'1'!$B$12) -> 0 | N11: Income
A12: Month | B12: {=_xlfn.TEXTAFTER(CELL("filename",A1),"]")} -> 2 | J12: Total | K12: =SUBTOTAL(109,Table916[Total]) -> 5475.5 | N12: Income
G13: INDIRECT("raport_"&$B$12-1&"[@[Closing balance ]]") | N13: Income
A14: Type | B14: Total | N14: Income
A15: Income | B15: =SUMIFS(operations[Amount],operations[Type],balance_2[[#This Row],[Type]],operations[Month],'1'!$B$12) -> 5655.5 | N15: Income
A16: Expense | B16: =SUMIFS(operations[Amount],operations[Type],balance_2[[#This Row],[Type]],operations[Month],'1'!$B$12) -> -4810 | N16: Income
A17: Transfer | B17: =SUMIFS(operations[Amount],operations[Type],balance_2[[#This Row],[Type]],operations[Month],'1'!$B$12) -> 0 | N17: Transfer
A18: Total | B18: =SUBTOTAL(109,balance_2[Total]) -> 845.5

Sheet 3
A1: Bank | B1: Product | C1: Opening balance | D1: Operation | E1: Closing balance | G1: Category | H1: Total | J1: Category | K1: Total | N1: Type
A2: Millennium | B2: Account | C2: {=INDIRECT("raport_"&$B$12-1&"[@[Closing balance ]]")} -> #REF! | D2: =SUMIFS(operations[Amount],operations[Bank],raports_3[[#This Row],[Bank]],operations[Product],raports_3[[#This Row],[Product]],operations[Month],$B$12) -> 67.5 | E2: =raports_3[[#This Row],[Opening balance]]+raports_3[[#This Row],[Operation]] -> #REF! | G2: Accomodation | H2: =SUMIFS(operations[Amount],operations[Category],Expenses3[[#This Row],[Category]],operations[Month],'1'!$B$12) -> -2000 | J2: Other expences | N2: Expense
A3: Millennium | B3: Savings account | C3: 10.5 | D3: =SUMIFS(operations[Amount],operations[Bank],raports_3[[#This Row],[Bank]],operations[Product],raports_3[[#This Row],[Product]],operations[Month],$B$12) -> 5 | E3: =raports_3[[#This Row],[Opening balance]]+raports_3[[#This Row],[Operation]] -> 15.5 | G3: Clothing | H3: =SUMIFS(operations[Amount],operations[Category],Expenses3[[#This Row],[Category]],operations[Month],'1'!$B$12) -> -80 | J3: Studies | K3: =SUMIFS(operations[Amount],operations[Category],Table91624[[#This Row],[Category]],operations[Month],'1'!$B$12) -> -100 | N3: Expense
A4: Santander | B4: Account | C4: 600 | D4: =SUMIFS(operations[Amount],operations[Bank],raports_3[[#This Row],[Bank]],operations[Product],raports_3[[#This Row],[Product]],operations[Month],$B$12) -> 821.6 | E4: =raports_3[[#This Row],[Opening balance]]+raports_3[[#This Row],[Operation]] -> 1421.6 | G4: Entertainment | H4: =SUMIFS(operations[Amount],operations[Category],Expenses3[[#This Row],[Category]],operations[Month],'1'!$B$12) -> -85 | J4: Transportation | K4: =SUMIFS(operations[Amount],operations[Category],Table91624[[#This Row],[Category]],operations[Month],'1'!$B$12) -> -80 | N4: Expense
A5: Santander | B5: Credit card | C5: 0 | D5: =SUMIFS(operations[Amount],operations[Bank],raports_3[[#This Row],[Bank]],operations[Product],raports_3[[#This Row],[Product]],operations[Month],$B$12) -> -104.5 | E5: =raports_3[[#This Row],[Opening balance]]+raports_3[[#This Row],[Operation]] -> -104.5 | G5: Groceries | H5: =SUMIFS(operations[Amount],operations[Category],Expenses3[[#This Row],[Category]],operations[Month],'1'!$B$12) -> -1715 | J5: Allowance | K5: =SUMIFS(operations[Amount],operations[Category],Table91624[[#This Row],[Category]],operations[Month],'1'!$B$12) -> 250 | N5: Expense
A6: Santander | B6: Fixed-term deposit | C6: 2000 | D6: =SUMIFS(operations[Amount],operations[Bank],raports_3[[#This Row],[Bank]],operations[Product],raports_3[[#This Row],[Product]],operations[Month],$B$12) -> 0 | E6: =raports_3[[#This Row],[Opening balance]]+raports_3[[#This Row],[Operation]] -> 2000 | G6: Health&Beauty | H6: =SUMIFS(operations[Amount],operations[Category],Expenses3[[#This Row],[Category]],operations[Month],'1'!$B$12) -> -100 | J6: Financial | K6: =SUMIFS(operations[Amount],operations[Category],Table91624[[#This Row],[Category]],operations[Month],'1'!$B$12) -> 105.5 | N6: Expense
A7: Wallet | B7: Gift card | C7: 200 | D7: =SUMIFS(operations[Amount],operations[Bank],raports_3[[#This Row],[Bank]],operations[Product],raports_3[[#This Row],[Product]],operations[Month],$B$12) -> -24.49 | E7: =raports_3[[#This Row],[Opening balance]]+raports_3[[#This Row],[Operation]] -> 175.51 | G7: Multimedia | H7: =SUMIFS(operations[Amount],operations[Category],Expenses3[[#This Row],[Category]],operations[Month],'1'!$B$12) -> -150 | J7: Gift | K7: =SUMIFS(operations[Amount],operations[Category],Table91624[[#This Row],[Category]],operations[Month],'1'!$B$12) -> 0 | N7: Expense
A8: Wallet | B8: Money | C8: 30 | D8: =SUMIFS(operations[Amount],operations[Bank],raports_3[[#This Row],[Bank]],operations[Product],raports_3[[#This Row],[Product]],operations[Month],$B$12) -> -9.5 | E8: =raports_3[[#This Row],[Opening balance]]+raports_3[[#This Row],[Operation]] -> 20.5 | G8: Total | H8: =SUBTOTAL(109,Expenses3[Total]) -> -4130 | J8: Other incoms | K8: =SUMIFS(operations[Amount],operations[Category],Table91624[[#This Row],[Category]],operations[Month],'1'!$B$12) -> 800 | N8: Expense
A9: Total | C9: =SUBTOTAL(109,raports_3[Opening balance]) -> #REF! | D9: =SUBTOTAL(109,raports_3[Operation]) -> 755.61 | E9: =SUBTOTAL(109,raports_3[Closing balance]) -> #REF! | J9: Salary | K9: =SUMIFS(operations[Amount],operations[Category],Table91624[[#This Row],[Category]],operations[Month],'1'!$B$12) -> 4500 | N9: Expense
J10: Scholarship | K10: =SUMIFS(operations[Amount],operations[Category],Table91624[[#This Row],[Category]],operations[Month],'1'!$B$12) -> 0 | N10: Expense
J11: Transfer | K11: =SUMIFS(operations[Amount],operations[Category],Table91624[[#This Row],[Category]],operations[Month],'1'!$B$12) -> 0 | N11: Income
A12: Month | B12: {=_xlfn.TEXTAFTER(CELL("filename",A1),"]")} -> 3 | J12: Total | K12: =SUBTOTAL(109,Table91624[Total]) -> 5475.5 | N12: Income
G13: INDIRECT("raport_"&$B$12-1&"[@[Closing balance ]]") | N13: Income
A14: Type | B14: Total | N14: Income
A15: Income | B15: =SUMIFS(operations[Amount],operations[Type],balance_3[[#This Row],[Type]],operations[Month],'1'!$B$12) -> 5655.5 | N15: Income
A16: Expense | B16: =SUMIFS(operations[Amount],operations[Type],balance_3[[#This Row],[Type]],operations[Month],'1'!$B$12) -> -4810 | N16: Income
A17: Transfer | B17: =SUMIFS(operations[Amount],operations[Type],balance_3[[#This Row],[Type]],operations[Month],'1'!$B$12) -> 0 | N17: Transfer
A18: Total | B18: =SUBTOTAL(109,balance_3[Total]) -> 845.5

Sheet 4
A1: Bank | B1: Product | C1: Opening balance | D1: Operation | E1: Closing balance | G1: Category | H1: Total | J1: Category | K1: Total | N1: Type
A2: Millennium | B2: Account | C2: {=INDIRECT("raport_"&$B$12-1&"[@[Closing balance ]]")} -> #REF! | D2: =SUMIFS(operations[Amount],operations[Bank],raports_4[[#This Row],[Bank]],operations[Product],raports_4[[#This Row],[Product]],operations[Month],$B$12) -> 101 | E2: =raports_4[[#This Row],[Opening balance]]+raports_4[[#This Row],[Operation]] -> #REF! | G2: Accomodation | H2: =SUMIFS(operations[Amount],operations[Category],Expenses4[[#This Row],[Category]],operations[Month],'1'!$B$12) -> -2000 | J2: Other expences | N2: Expense
A3: Millennium | B3: Savings account | C3: 10.5 | D3: =SUMIFS(operations[Amount],operations[Bank],raports_4[[#This Row],[Bank]],operations[Product],raports_4[[#This Row],[Product]],operations[Month],$B$12) -> 50 | E3: =raports_4[[#This Row],[Opening balance]]+raports_4[[#This Row],[Operation]] -> 60.5 | G3: Clothing | H3: =SUMIFS(operations[Amount],operations[Category],Expenses4[[#This Row],[Category]],operations[Month],'1'!$B$12) -> -80 | J3: Studies | K3: =SUMIFS(operations[Amount],operations[Category],Table91628[[#This Row],[Category]],operations[Month],'1'!$B$12) -> -100 | N3: Expense
A4: Santander | B4: Account | C4: 600 | D4: =SUMIFS(operations[Amount],operations[Bank],raports_4[[#This Row],[Bank]],operations[Product],raports_4[[#This Row],[Product]],operations[Month],$B$12) -> 562.73 | E4: =raports_4[[#This Row],[Opening balance]]+raports_4[[#This Row],[Operation]] -> 1162.73 | G4: Entertainment | H4: =SUMIFS(operations[Amount],operations[Category],Expenses4[[#This Row],[Category]],operations[Month],'1'!$B$12) -> -85 | J4: Transportation | K4: =SUMIFS(operations[Amount],operations[Category],Table91628[[#This Row],[Category]],operations[Month],'1'!$B$12) -> -80 | N4: Expense
A5: Santander | B5: Credit card | C5: 0 | D5: =SUMIFS(operations[Amount],operations[Bank],raports_4[[#This Row],[Bank]],operations[Product],raports_4[[#This Row],[Product]],operations[Month],$B$12) -> 13.11 | E5: =raports_4[[#This Row],[Opening balance]]+raports_4[[#This Row],[Operation]] -> 13.11 | G5: Groceries | H5: =SUMIFS(operations[Amount],operations[Category],Expenses4[[#This Row],[Category]],operations[Month],'1'!$B$12) -> -1715 | J5: Allowance | K5: =SUMIFS(operations[Amount],operations[Category],Table91628[[#This Row],[Category]],operations[Month],'1'!$B$12) -> 250 | N5: Expense
A6: Santander | B6: Fixed-term deposit | C6: 2000 | D6: =SUMIFS(operations[Amount],operations[Bank],raports_4[[#This Row],[Bank]],operations[Product],raports_4[[#This Row],[Product]],operations[Month],$B$12) -> 0 | E6: =raports_4[[#This Row],[Opening balance]]+raports_4[[#This Row],[Operation]] -> 2000 | G6: Health&Beauty | H6: =SUMIFS(operations[Amount],operations[Category],Expenses4[[#This Row],[Category]],operations[Month],'1'!$B$12) -> -100 | J6: Financial | K6: =SUMIFS(operations[Amount],operations[Category],Table91628[[#This Row],[Category]],operations[Month],'1'!$B$12) -> 105.5 | N6: Expense
A7: Wallet | B7: Gift card | C7: 200 | D7: =SUMIFS(operations[Amount],operations[Bank],raports_4[[#This Row],[Bank]],operations[Product],raports_4[[#This Row],[Product]],operations[Month],$B$12) -> 0 | E7: =raports_4[[#This Row],[Opening balance]]+raports_4[[#This Row],[Operation]] -> 200 | G7: Multimedia | H7: =SUMIFS(operations[Amount],operations[Category],Expenses4[[#This Row],[Category]],operations[Month],'1'!$B$12) -> -150 | J7: Gift | K7: =SUMIFS(operations[Amount],operations[Category],Table91628[[#This Row],[Category]],operations[Month],'1'!$B$12) -> 0 | N7: Expense
A8: Wallet | B8: Money | C8: 30 | D8: =SUMIFS(operations[Amount],operations[Bank],raports_4[[#This Row],[Bank]],operations[Product],raports_4[[#This Row],[Product]],operations[Month],$B$12) -> 0 | E8: =raports_4[[#This Row],[Opening balance]]+raports_4[[#This Row],[Operation]] -> 30 | G8: Total | H8: =SUBTOTAL(109,Expenses4[Total]) -> -4130 | J8: Other incoms | K8: =SUMIFS(operations[Amount],operations[Category],Table91628[[#This Row],[Category]],operations[Month],'1'!$B$12) -> 800 | N8: Expense
A9: Total | C9: =SUBTOTAL(109,raports_4[Opening balance]) -> #REF! | D9: =SUBTOTAL(109,raports_4[Operation]) -> 726.84 | E9: =SUBTOTAL(109,raports_4[Closing balance]) -> #REF! | J9: Salary | K9: =SUMIFS(operations[Amount],operations[Category],Table91628[[#This Row],[Category]],operations[Month],'1'!$B$12) -> 4500 | N9: Expense
J10: Scholarship | K10: =SUMIFS(operations[Amount],operations[Category],Table91628[[#This Row],[Category]],operations[Month],'1'!$B$12) -> 0 | N10: Expense
J11: Transfer | K11: =SUMIFS(operations[Amount],operations[Category],Table91628[[#This Row],[Category]],operations[Month],'1'!$B$12) -> 0 | N11: Income
A12: Month | B12: {=_xlfn.TEXTAFTER(CELL("filename",A1),"]")} -> 4 | J12: Total | K12: =SUBTOTAL(109,Table91628[Total]) -> 5475.5 | N12: Income
G13: INDIRECT("raport_"&$B$12-1&"[@[Closing balance ]]") | N13: Income
A14: Type | B14: Total | N14: Income
A15: Income | B15: =SUMIFS(operations[Amount],operations[Type],balance_4[[#This Row],[Type]],operations[Month],'1'!$B$12) -> 5655.5 | N15: Income
A16: Expense | B16: =SUMIFS(operations[Amount],operations[Type],balance_4[[#This Row],[Type]],operations[Month],'1'!$B$12) -> -4810 | N16: Income
A17: Transfer | B17: =SUMIFS(operations[Amount],operations[Type],balance_4[[#This Row],[Type]],operations[Month],'1'!$B$12) -> 0 | N17: Transfer
A18: Total | B18: =SUBTOTAL(109,balance_4[Total]) -> 845.5

Sheet 5
A1: Bank | B1: Product | C1: Opening balance | D1: Operation | E1: Closing balance | G1: Category | H1: Total | J1: Category | K1: Total | N1: Type
A2: Millennium | B2: Account | C2: {=INDIRECT("raport_"&$B$12-1&"[@[Closing balance ]]")} -> #REF! | D2: =SUMIFS(operations[Amount],operations[Bank],raports_6[[#This Row],[Bank]],operations[Product],raports_6[[#This Row],[Product]],operations[Month],$B$12) -> -50 | E2: =raports_6[[#This Row],[Opening balance]]+raports_6[[#This Row],[Operation]] -> #REF! | G2: Accomodation | H2: =SUMIFS(operations[Amount],operations[Category],Expenses5[[#This Row],[Category]],operations[Month],'1'!$B$12) -> -2000 | J2: Other expences | N2: Expense
A3: Millennium | B3: Savings account | C3: 10.5 | D3: =SUMIFS(operations[Amount],operations[Bank],raports_6[[#This Row],[Bank]],operations[Product],raports_6[[#This Row],[Product]],operations[Month],$B$12) -> 0 | E3: =raports_6[[#This Row],[Opening balance]]+raports_6[[#This Row],[Operation]] -> 10.5 | G3: Clothing | H3: =SUMIFS(operations[Amount],operations[Category],Expenses5[[#This Row],[Category]],operations[Month],'1'!$B$12) -> -80 | J3: Studies | K3: =SUMIFS(operations[Amount],operations[Category],Table9162832[[#This Row],[Category]],operations[Month],'1'!$B$12) -> -100 | N3: Expense
A4: Santander | B4: Account | C4: 600 | D4: =SUMIFS(operations[Amount],operations[Bank],raports_6[[#This Row],[Bank]],operations[Product],raports_6[[#This Row],[Product]],operations[Month],$B$12) -> 2328.61 | E4: =raports_6[[#This Row],[Opening balance]]+raports_6[[#This Row],[Operation]] -> 2928.61 | G4: Entertainment | H4: =SUMIFS(operations[Amount],operations[Category],Expenses5[[#This Row],[Category]],operations[Month],'1'!$B$12) -> -85 | J4: Transportation | K4: =SUMIFS(operations[Amount],operations[Category],Table9162832[[#This Row],[Category]],operations[Month],'1'!$B$12) -> -80 | N4: Expense
A5: Santander | B5: Credit card | C5: 0 | D5: =SUMIFS(operations[Amount],operations[Bank],raports_6[[#This Row],[Bank]],operations[Product],raports_6[[#This Row],[Product]],operations[Month],$B$12) -> -908.61 | E5: =raports_6[[#This Row],[Opening balance]]+raports_6[[#This Row],[Operation]] -> -908.61 | G5: Groceries | H5: =SUMIFS(operations[Amount],operations[Category],Expenses5[[#This Row],[Category]],operations[Month],'1'!$B$12) -> -1715 | J5: Allowance | K5: =SUMIFS(operations[Amount],operations[Category],Table9162832[[#This Row],[Category]],operations[Month],'1'!$B$12) -> 250 | N5: Expense
A6: Santander | B6: Fixed-term deposit | C6: 2000 | D6: =SUMIFS(operations[Amount],operations[Bank],raports_6[[#This Row],[Bank]],operations[Product],raports_6[[#This Row],[Product]],operations[Month],$B$12) -> 0 | E6: =raports_6[[#This Row],[Opening balance]]+raports_6[[#This Row],[Operation]] -> 2000 | G6: Health&Beauty | H6: =SUMIFS(operations[Amount],operations[Category],Expenses5[[#This Row],[Category]],operations[Month],'1'!$B$12) -> -100 | J6: Financial | K6: =SUMIFS(operations[Amount],operations[Category],Table9162832[[#This Row],[Category]],operations[Month],'1'!$B$12) -> 105.5 | N6: Expense
A7: Wallet | B7: Gift card | C7: 200 | D7: =SUMIFS(operations[Amount],operations[Bank],raports_6[[#This Row],[Bank]],operations[Product],raports_6[[#This Row],[Product]],operations[Month],$B$12) -> 0 | E7: =raports_6[[#This Row],[Opening balance]]+raports_6[[#This Row],[Operation]] -> 200 | G7: Multimedia | H7: =SUMIFS(operations[Amount],operations[Category],Expenses5[[#This Row],[Category]],operations[Month],'1'!$B$12) -> -150 | J7: Gift | K7: =SUMIFS(operations[Amount],operations[Category],Table9162832[[#This Row],[Category]],operations[Month],'1'!$B$12) -> 0 | N7: Expense
A8: Wallet | B8: Money | C8: 30 | D8: =SUMIFS(operations[Amount],operations[Bank],raports_6[[#This Row],[Bank]],operations[Product],raports_6[[#This Row],[Product]],operations[Month],$B$12) -> -80 | E8: =raports_6[[#This Row],[Opening balance]]+raports_6[[#This Row],[Operation]] -> -50 | G8: Total | H8: =SUBTOTAL(109,Expenses5[Total]) -> -4130 | J8: Other incoms | K8: =SUMIFS(operations[Amount],operations[Category],Table9162832[[#This Row],[Category]],operations[Month],'1'!$B$12) -> 800 | N8: Expense
A9: Total | C9: =SUBTOTAL(109,raports_6[Opening balance]) -> #REF! | D9: =SUBTOTAL(109,raports_6[Operation]) -> 1290 | E9: =SUBTOTAL(109,raports_6[Closing balance]) -> #REF! | J9: Salary | K9: =SUMIFS(operations[Amount],operations[Category],Table9162832[[#This Row],[Category]],operations[Month],'1'!$B$12) -> 4500 | N9: Expense
J10: Scholarship | K10: =SUMIFS(operations[Amount],operations[Category],Table9162832[[#This Row],[Category]],operations[Month],'1'!$B$12) -> 0 | N10: Expense
J11: Transfer | K11: =SUMIFS(operations[Amount],operations[Category],Table9162832[[#This Row],[Category]],operations[Month],'1'!$B$12) -> 0 | N11: Income
A12: Month | B12: {=_xlfn.TEXTAFTER(CELL("filename",A1),"]")} -> 5 | J12: Total | K12: =SUBTOTAL(109,Table9162832[Total]) -> 5475.5 | N12: Income
G13: INDIRECT("raport_"&$B$12-1&"[@[Closing balance ]]") | N13: Income
A14: Type | B14: Total | N14: Income
A15: Income | B15: =SUMIFS(operations[Amount],operations[Type],balance_5[[#This Row],[Type]],operations[Month],'1'!$B$12) -> 5655.5 | N15: Income
A16: Expense | B16: =SUMIFS(operations[Amount],operations[Type],balance_5[[#This Row],[Type]],operations[Month],'1'!$B$12) -> -4810 | N16: Income
A17: Transfer | B17: =SUMIFS(operations[Amount],operations[Type],balance_5[[#This Row],[Type]],operations[Month],'1'!$B$12) -> 0 | N17: Transfer
A18: Total | B18: =SUBTOTAL(109,balance_5[Total]) -> 845.5

Sheet 6
A1: Bank | B1: Product | C1: Opening balance | D1: Operation | E1: Closing balance | G1: Category | H1: Total | J1: Category | K1: Total | N1: Type
A2: Millennium | B2: Account | C2: {=INDIRECT("raport_"&$B$12-1&"[@[Closing balance ]]")} -> #REF! | D2: =SUMIFS(operations[Amount],operations[Bank],raports_5[[#This Row],[Bank]],operations[Product],raports_5[[#This Row],[Product]],operations[Month],$B$12) -> 250 | E2: =raports_5[[#This Row],[Opening balance]]+raports_5[[#This Row],[Operation]] -> #REF! | G2: Accomodation | H2: =SUMIFS(operations[Amount],operations[Category],Expenses6[[#This Row],[Category]],operations[Month],'1'!$B$12) -> -2000 | J2: Other expences | N2: Expense
A3: Millennium | B3: Savings account | C3: 10.5 | D3: =SUMIFS(operations[Amount],operations[Bank],raports_5[[#This Row],[Bank]],operations[Product],raports_5[[#This Row],[Product]],operations[Month],$B$12) -> 0 | E3: =raports_5[[#This Row],[Opening balance]]+raports_5[[#This Row],[Operation]] -> 10.5 | G3: Clothing | H3: =SUMIFS(operations[Amount],operations[Category],Expenses6[[#This Row],[Category]],operations[Month],'1'!$B$12) -> -80 | J3: Studies | K3: =SUMIFS(operations[Amount],operations[Category],Table916283236[[#This Row],[Category]],operations[Month],'1'!$B$12) -> -100 | N3: Expense
A4: Santander | B4: Account | C4: 600 | D4: =SUMIFS(operations[Amount],operations[Bank],raports_5[[#This Row],[Bank]],operations[Product],raports_5[[#This Row],[Product]],operations[Month],$B$12) -> 1420 | E4: =raports_5[[#This Row],[Opening balance]]+raports_5[[#This Row],[Operation]] -> 2020 | G4: Entertainment | H4: =SUMIFS(operations[Amount],operations[Category],Expenses6[[#This Row],[Category]],operations[Month],'1'!$B$12) -> -85 | J4: Transportation | K4: =SUMIFS(operations[Amount],operations[Category],Table916283236[[#This Row],[Category]],operations[Month],'1'!$B$12) -> -80 | N4: Expense
A5: Santander | B5: Credit card | C5: 0 | D5: =SUMIFS(operations[Amount],operations[Bank],raports_5[[#This Row],[Bank]],operations[Product],raports_5[[#This Row],[Product]],operations[Month],$B$12) -> -300 | E5: =raports_5[[#This Row],[Opening balance]]+raports_5[[#This Row],[Operation]] -> -300 | G5: Groceries | H5: =SUMIFS(operations[Amount],operations[Category],Expenses6[[#This Row],[Category]],operations[Month],'1'!$B$12) -> -1715 | J5: Allowance | K5: =SUMIFS(operations[Amount],operations[Category],Table916283236[[#This Row],[Category]],operations[Month],'1'!$B$12) -> 250 | N5: Expense
A6: Santander | B6: Fixed-term deposit | C6: 2000 | D6: =SUMIFS(operations[Amount],operations[Bank],raports_5[[#This Row],[Bank]],operations[Product],raports_5[[#This Row],[Product]],operations[Month],$B$12) -> 0 | E6: =raports_5[[#This Row],[Opening balance]]+raports_5[[#This Row],[Operation]] -> 2000 | G6: Health&Beauty | H6: =SUMIFS(operations[Amount],operations[Category],Expenses6[[#This Row],[Category]],operations[Month],'1'!$B$12) -> -100 | J6: Financial | K6: =SUMIFS(operations[Amount],operations[Category],Table916283236[[#This Row],[Category]],operations[Month],'1'!$B$12) -> 105.5 | N6: Expense
A7: Wallet | B7: Gift card | C7: 200 | D7: =SUMIFS(operations[Amount],operations[Bank],raports_5[[#This Row],[Bank]],operations[Product],raports_5[[#This Row],[Product]],operations[Month],$B$12) -> 0 | E7: =raports_5[[#This Row],[Opening balance]]+raports_5[[#This Row],[Operation]] -> 200 | G7: Multimedia | H7: =SUMIFS(operations[Amount],operations[Category],Expenses6[[#This Row],[Category]],operations[Month],'1'!$B$12) -> -150 | J7: Gift | K7: =SUMIFS(operations[Amount],operations[Category],Table916283236[[#This Row],[Category]],operations[Month],'1'!$B$12) -> 0 | N7: Expense
A8: Wallet | B8: Money | C8: 30 | D8: =SUMIFS(operations[Amount],operations[Bank],raports_5[[#This Row],[Bank]],operations[Product],raports_5[[#This Row],[Product]],operations[Month],$B$12) -> -200 | E8: =raports_5[[#This Row],[Opening balance]]+raports_5[[#This Row],[Operation]] -> -170 | G8: Total | H8: =SUBTOTAL(109,Expenses6[Total]) -> -4130 | J8: Other incoms | K8: =SUMIFS(operations[Amount],operations[Category],Table916283236[[#This Row],[Category]],operations[Month],'1'!$B$12) -> 800 | N8: Expense
A9: Total | C9: =SUBTOTAL(109,raports_5[Opening balance]) -> #REF! | D9: =SUBTOTAL(109,raports_5[Operation]) -> 1170 | E9: =SUBTOTAL(109,raports_5[Closing balance]) -> #REF! | J9: Salary | K9: =SUMIFS(operations[Amount],operations[Category],Table916283236[[#This Row],[Category]],operations[Month],'1'!$B$12) -> 4500 | N9: Expense
J10: Scholarship | K10: =SUMIFS(operations[Amount],operations[Category],Table916283236[[#This Row],[Category]],operations[Month],'1'!$B$12) -> 0 | N10: Expense
J11: Transfer | K11: =SUMIFS(operations[Amount],operations[Category],Table916283236[[#This Row],[Category]],operations[Month],'1'!$B$12) -> 0 | N11: Income
A12: Month | B12: {=_xlfn.TEXTAFTER(CELL("filename",A1),"]")} -> 6 | J12: Total | K12: =SUBTOTAL(109,Table916283236[Total]) -> 5475.5 | N12: Income
G13: INDIRECT("raport_"&$B$12-1&"[@[Closing balance ]]") | N13: Income
A14: Type | B14: Total | N14: Income
A15: Income | B15: =SUMIFS(operations[Amount],operations[Type],balance_6[[#This Row],[Type]],operations[Month],'1'!$B$12) -> 5655.5 | N15: Income
A16: Expense | B16: =SUMIFS(operations[Amount],operations[Type],balance_6[[#This Row],[Type]],operations[Month],'1'!$B$12) -> -4810 | N16: Income
A17: Transfer | B17: =SUMIFS(operations[Amount],operations[Type],balance_6[[#This Row],[Type]],operations[Month],'1'!$B$12) -> 0 | N17: Transfer
A18: Total | B18: =SUBTOTAL(109,balance_6[Total]) -> 845.5

Sheet 7
A1: Bank | B1: Product | C1: Opening balance | D1: Operation | E1: Closing balance | G1: Category | H1: Total | J1: Category | K1: Total | N1: Type
A2: Millennium | B2: Account | C2: {=INDIRECT("raport_"&$B$12-1&"[@[Closing balance ]]")} -> #REF! | D2: =SUMIFS(operations[Amount],operations[Bank],raports_7[[#This Row],[Bank]],operations[Product],raports_7[[#This Row],[Product]],operations[Month],$B$12) -> -100 | E2: =raports_7[[#This Row],[Opening balance]]+raports_7[[#This Row],[Operation]] -> #REF! | G2: Accomodation | H2: =SUMIFS(operations[Amount],operations[Category],Expenses7[[#This Row],[Category]],operations[Month],'1'!$B$12) -> -2000 | J2: Other expences | N2: Expense
A3: Millennium | B3: Savings account | C3: 10.5 | D3: =SUMIFS(operations[Amount],operations[Bank],raports_7[[#This Row],[Bank]],operations[Product],raports_7[[#This Row],[Product]],operations[Month],$B$12) -> 1050 | E3: =raports_7[[#This Row],[Opening balance]]+raports_7[[#This Row],[Operation]] -> 1060.5 | G3: Clothing | H3: =SUMIFS(operations[Amount],operations[Category],Expenses7[[#This Row],[Category]],operations[Month],'1'!$B$12) -> -80 | J3: Studies | K3: =SUMIFS(operations[Amount],operations[Category],Table91628323640[[#This Row],[Category]],operations[Month],'1'!$B$12) -> -100 | N3: Expense
A4: Santander | B4: Account | C4: 600 | D4: =SUMIFS(operations[Amount],operations[Bank],raports_7[[#This Row],[Bank]],operations[Product],raports_7[[#This Row],[Product]],operations[Month],$B$12) -> 1010 | E4: =raports_7[[#This Row],[Opening balance]]+raports_7[[#This Row],[Operation]] -> 1610 | G4: Entertainment | H4: =SUMIFS(operations[Amount],operations[Category],Expenses7[[#This Row],[Category]],operations[Month],'1'!$B$12) -> -85 | J4: Transportation | K4: =SUMIFS(operations[Amount],operations[Category],Table91628323640[[#This Row],[Category]],operations[Month],'1'!$B$12) -> -80 | N4: Expense
A5: Santander | B5: Credit card | C5: 0 | D5: =SUMIFS(operations[Amount],operations[Bank],raports_7[[#This Row],[Bank]],operations[Product],raports_7[[#This Row],[Product]],operations[Month],$B$12) -> 1165 | E5: =raports_7[[#This Row],[Opening balance]]+raports_7[[#This Row],[Operation]] -> 1165 | G5: Groceries | H5: =SUMIFS(operations[Amount],operations[Category],Expenses7[[#This Row],[Category]],operations[Month],'1'!$B$12) -> -1715 | J5: Allowance | K5: =SUMIFS(operations[Amount],operations[Category],Table91628323640[[#This Row],[Category]],operations[Month],'1'!$B$12) -> 250 | N5: Expense
A6: Santander | B6: Fixed-term deposit | C6: 2000 | D6: =SUMIFS(operations[Amount],operations[Bank],raports_7[[#This Row],[Bank]],operations[Product],raports_7[[#This Row],[Product]],operations[Month],$B$12) -> -180 | E6: =raports_7[[#This Row],[Opening balance]]+raports_7[[#This Row],[Operation]] -> 1820 | G6: Health&Beauty | H6: =SUMIFS(operations[Amount],operations[Category],Expenses7[[#This Row],[Category]],operations[Month],'1'!$B$12) -> -100 | J6: Financial | K6: =SUMIFS(operations[Amount],operations[Category],Table91628323640[[#This Row],[Category]],operations[Month],'1'!$B$12) -> 105.5 | N6: Expense
A7: Wallet | B7: Gift card | C7: 200 | D7: =SUMIFS(operations[Amount],operations[Bank],raports_7[[#This Row],[Bank]],operations[Product],raports_7[[#This Row],[Product]],operations[Month],$B$12) -> -30 | E7: =raports_7[[#This Row],[Opening balance]]+raports_7[[#This Row],[Operation]] -> 170 | G7: Multimedia | H7: =SUMIFS(operations[Amount],operations[Category],Expenses7[[#This Row],[Category]],operations[Month],'1'!$B$12) -> -150 | J7: Gift | K7: =SUMIFS(operations[Amount],operations[Category],Table91628323640[[#This Row],[Category]],operations[Month],'1'!$B$12) -> 0 | N7: Expense
A8: Wallet | B8: Money | C8: 30 | D8: =SUMIFS(operations[Amount],operations[Bank],raports_7[[#This Row],[Bank]],operations[Product],raports_7[[#This Row],[Product]],operations[Month],$B$12) -> 0 | E8: =raports_7[[#This Row],[Opening balance]]+raports_7[[#This Row],[Operation]] -> 30 | G8: Total | H8: =SUBTOTAL(109,Expenses7[Total]) -> -4130 | J8: Other incoms | K8: =SUMIFS(operations[Amount],operations[Category],Table91628323640[[#This Row],[Category]],operations[Month],'1'!$B$12) -> 800 | N8: Expense
A9: Total | C9: =SUBTOTAL(109,raports_7[Opening balance]) -> #REF! | D9: =SUBTOTAL(109,raports_7[Operation]) -> 2915 | E9: =SUBTOTAL(109,raports_7[Closing balance]) -> #REF! | J9: Salary | K9: =SUMIFS(operations[Amount],operations[Category],Table91628323640[[#This Row],[Category]],operations[Month],'1'!$B$12) -> 4500 | N9: Expense
J10: Scholarship | K10: =SUMIFS(operations[Amount],operations[Category],Table91628323640[[#This Row],[Category]],operations[Month],'1'!$B$12) -> 0 | N10: Expense
J11: Transfer | K11: =SUMIFS(operations[Amount],operations[Category],Table91628323640[[#This Row],[Category]],operations[Month],'1'!$B$12) -> 0 | N11: Income
A12: Month | B12: {=_xlfn.TEXTAFTER(CELL("filename",A1),"]")} -> 7 | J12: Total | K12: =SUBTOTAL(109,Table91628323640[Total]) -> 5475.5 | N12: Income
G13: INDIRECT("raport_"&$B$12-1&"[@[Closing balance ]]") | N13: Income
A14: Type | B14: Total | N14: Income
A15: Income | B15: =SUMIFS(operations[Amount],operations[Type],balance_7[[#This Row],[Type]],operations[Month],'1'!$B$12) -> 5655.5 | N15: Income
A16: Expense | B16: =SUMIFS(operations[Amount],operations[Type],balance_7[[#This Row],[Type]],operations[Month],'1'!$B$12) -> -4810 | N16: Income
A17: Transfer | B17: =SUMIFS(operations[Amount],operations[Type],balance_7[[#This Row],[Type]],operations[Month],'1'!$B$12) -> 0 | N17: Transfer
A18: Total | B18: =SUBTOTAL(109,balance_7[Total]) -> 845.5

Sheet 8
A1: Bank | B1: Product | C1: Opening balance | D1: Operation | E1: Closing balance | G1: Category | H1: Total | J1: Category | K1: Total | N1: Type
A2: Millennium | B2: Account | C2: {=INDIRECT("raport_"&$B$12-1&"[@[Closing balance ]]")} -> #REF! | D2: =SUMIFS(operations[Amount],operations[Bank],raports_8[[#This Row],[Bank]],operations[Product],raports_8[[#This Row],[Product]],operations[Month],$B$12) -> 200 | E2: =raports_8[[#This Row],[Opening balance]]+raports_8[[#This Row],[Operation]] -> #REF! | G2: Accomodation | H2: =SUMIFS(operations[Amount],operations[Category],Expenses8[[#This Row],[Category]],operations[Month],'1'!$B$12) -> -2000 | J2: Other expences | N2: Expense
A3: Millennium | B3: Savings account | C3: 10.5 | D3: =SUMIFS(operations[Amount],operations[Bank],raports_8[[#This Row],[Bank]],operations[Product],raports_8[[#This Row],[Product]],operations[Month],$B$12) -> -300 | E3: =raports_8[[#This Row],[Opening balance]]+raports_8[[#This Row],[Operation]] -> -289.5 | G3: Clothing | H3: =SUMIFS(operations[Amount],operations[Category],Expenses8[[#This Row],[Category]],operations[Month],'1'!$B$12) -> -80 | J3: Studies | K3: =SUMIFS(operations[Amount],operations[Category],Table9162832364044[[#This Row],[Category]],operations[Month],'1'!$B$12) -> -100 | N3: Expense
A4: Santander | B4: Account | C4: 600 | D4: =SUMIFS(operations[Amount],operations[Bank],raports_8[[#This Row],[Bank]],operations[Product],raports_8[[#This Row],[Product]],operations[Month],$B$12) -> 1475 | E4: =raports_8[[#This Row],[Opening balance]]+raports_8[[#This Row],[Operation]] -> 2075 | G4: Entertainment | H4: =SUMIFS(operations[Amount],operations[Category],Expenses8[[#This Row],[Category]],operations[Month],'1'!$B$12) -> -85 | J4: Transportation | K4: =SUMIFS(operations[Amount],operations[Category],Table9162832364044[[#This Row],[Category]],operations[Month],'1'!$B$12) -> -80 | N4: Expense
A5: Santander | B5: Credit card | C5: 0 | D5: =SUMIFS(operations[Amount],operations[Bank],raports_8[[#This Row],[Bank]],operations[Product],raports_8[[#This Row],[Product]],operations[Month],$B$12) -> 33 | E5: =raports_8[[#This Row],[Opening balance]]+raports_8[[#This Row],[Operation]] -> 33 | G5: Groceries | H5: =SUMIFS(operations[Amount],operations[Category],Expenses8[[#This Row],[Category]],operations[Month],'1'!$B$12) -> -1715 | J5: Allowance | K5: =SUMIFS(operations[Amount],operations[Category],Table9162832364044[[#This Row],[Category]],operations[Month],'1'!$B$12) -> 250 | N5: Expense
A6: Santander | B6: Fixed-term deposit | C6: 2000 | D6: =SUMIFS(operations[Amount],operations[Bank],raports_8[[#This Row],[Bank]],operations[Product],raports_8[[#This Row],[Product]],operations[Month],$B$12) -> -1020 | E6: =raports_8[[#This Row],[Opening balance]]+raports_8[[#This Row],[Operation]] -> 980 | G6: Health&Beauty | H6: =SUMIFS(operations[Amount],operations[Category],Expenses8[[#This Row],[Category]],operations[Month],'1'!$B$12) -> -100 | J6: Financial | K6: =SUMIFS(operations[Amount],operations[Category],Table9162832364044[[#This Row],[Category]],operations[Month],'1'!$B$12) -> 105.5 | N6: Expense
A7: Wallet | B7: Gift card | C7: 200 | D7: =SUMIFS(operations[Amount],operations[Bank],raports_8[[#This Row],[Bank]],operations[Product],raports_8[[#This Row],[Product]],operations[Month],$B$12) -> 0 | E7: =raports_8[[#This Row],[Opening balance]]+raports_8[[#This Row],[Operation]] -> 200 | G7: Multimedia | H7: =SUMIFS(operations[Amount],operations[Category],Expenses8[[#This Row],[Category]],operations[Month],'1'!$B$12) -> -150 | J7: Gift | K7: =SUMIFS(operations[Amount],operations[Category],Table9162832364044[[#This Row],[Category]],operations[Month],'1'!$B$12) -> 0 | N7: Expense
A8: Wallet | B8: Money | C8: 30 | D8: =SUMIFS(operations[Amount],operations[Bank],raports_8[[#This Row],[Bank]],operations[Product],raports_8[[#This Row],[Product]],operations[Month],$B$12) -> 2.5 | E8: =raports_8[[#This Row],[Opening balance]]+raports_8[[#This Row],[Operation]] -> 32.5 | G8: Total | H8: =SUBTOTAL(109,Expenses8[Total]) -> -4130 | J8: Other incoms | K8: =SUMIFS(operations[Amount],operations[Category],Table9162832364044[[#This Row],[Category]],operations[Month],'1'!$B$12) -> 800 | N8: Expense
A9: Total | C9: =SUBTOTAL(109,raports_8[Opening balance]) -> #REF! | D9: =SUBTOTAL(109,raports_8[Operation]) -> 390.5 | E9: =SUBTOTAL(109,raports_8[Closing balance]) -> #REF! | J9: Salary | K9: =SUMIFS(operations[Amount],operations[Category],Table9162832364044[[#This Row],[Category]],operations[Month],'1'!$B$12) -> 4500 | N9: Expense
J10: Scholarship | K10: =SUMIFS(operations[Amount],operations[Category],Table9162832364044[[#This Row],[Category]],operations[Month],'1'!$B$12) -> 0 | N10: Expense
J11: Transfer | K11: =SUMIFS(operations[Amount],operations[Category],Table9162832364044[[#This Row],[Category]],operations[Month],'1'!$B$12) -> 0 | N11: Income
A12: Month | B12: {=_xlfn.TEXTAFTER(CELL("filename",A1),"]")} -> 8 | J12: Total | K12: =SUBTOTAL(109,Table9162832364044[Total]) -> 5475.5 | N12: Income
G13: INDIRECT("raport_"&$B$12-1&"[@[Closing balance ]]") | N13: Income
A14: Type | B14: Total | N14: Income
A15: Income | B15: =SUMIFS(operations[Amount],operations[Type],balance_8[[#This Row],[Type]],operations[Month],'1'!$B$12) -> 5655.5 | N15: Income
A16: Expense | B16: =SUMIFS(operations[Amount],operations[Type],balance_8[[#This Row],[Type]],operations[Month],'1'!$B$12) -> -4810 | N16: Income
A17: Transfer | B17: =SUMIFS(operations[Amount],operations[Type],balance_8[[#This Row],[Type]],operations[Month],'1'!$B$12) -> 0 | N17: Transfer
A18: Total | B18: =SUBTOTAL(109,balance_8[Total]) -> 845.5

Sheet 9
A1: Bank | B1: Product | C1: Opening balance | D1: Operation | E1: Closing balance | G1: Category | H1: Total | J1: Category | K1: Total | N1: Type
A2: Millennium | B2: Account | C2: {=INDIRECT("raport_"&$B$12-1&"[@[Closing balance ]]")} -> #REF! | D2: =SUMIFS(operations[Amount],operations[Bank],raports_9[[#This Row],[Bank]],operations[Product],raports_9[[#This Row],[Product]],operations[Month],$B$12) -> -20 | E2: =raports_9[[#This Row],[Opening balance]]+raports_9[[#This Row],[Operation]] -> #REF! | G2: Accomodation | H2: =SUMIFS(operations[Amount],operations[Category],Expenses9[[#This Row],[Category]],operations[Month],'1'!$B$12) -> -2000 | J2: Other expences | N2: Expense
A3: Millennium | B3: Savings account | C3: 10.5 | D3: =SUMIFS(operations[Amount],operations[Bank],raports_9[[#This Row],[Bank]],operations[Product],raports_9[[#This Row],[Product]],operations[Month],$B$12) -> 0 | E3: =raports_9[[#This Row],[Opening balance]]+raports_9[[#This Row],[Operation]] -> 10.5 | G3: Clothing | H3: =SUMIFS(operations[Amount],operations[Category],Expenses9[[#This Row],[Category]],operations[Month],'1'!$B$12) -> -80 | J3: Studies | K3: =SUMIFS(operations[Amount],operations[Category],Table916283236404448[[#This Row],[Category]],operations[Month],'1'!$B$12) -> -100 | N3: Expense
A4: Santander | B4: Account | C4: 600 | D4: =SUMIFS(operations[Amount],operations[Bank],raports_9[[#This Row],[Bank]],operations[Product],raports_9[[#This Row],[Product]],operations[Month],$B$12) -> 1689.5 | E4: =raports_9[[#This Row],[Opening balance]]+raports_9[[#This Row],[Operation]] -> 2289.5 | G4: Entertainment | H4: =SUMIFS(operations[Amount],operations[Category],Expenses9[[#This Row],[Category]],operations[Month],'1'!$B$12) -> -85 | J4: Transportation | K4: =SUMIFS(operations[Amount],operations[Category],Table916283236404448[[#This Row],[Category]],operations[Month],'1'!$B$12) -> -80 | N4: Expense
A5: Santander | B5: Credit card | C5: 0 | D5: =SUMIFS(operations[Amount],operations[Bank],raports_9[[#This Row],[Bank]],operations[Product],raports_9[[#This Row],[Product]],operations[Month],$B$12) -> 82 | E5: =raports_9[[#This Row],[Opening balance]]+raports_9[[#This Row],[Operation]] -> 82 | G5: Groceries | H5: =SUMIFS(operations[Amount],operations[Category],Expenses9[[#This Row],[Category]],operations[Month],'1'!$B$12) -> -1715 | J5: Allowance | K5: =SUMIFS(operations[Amount],operations[Category],Table916283236404448[[#This Row],[Category]],operations[Month],'1'!$B$12) -> 250 | N5: Expense
A6: Santander | B6: Fixed-term deposit | C6: 2000 | D6: =SUMIFS(operations[Amount],operations[Bank],raports_9[[#This Row],[Bank]],operations[Product],raports_9[[#This Row],[Product]],operations[Month],$B$12) -> 0 | E6: =raports_9[[#This Row],[Opening balance]]+raports_9[[#This Row],[Operation]] -> 2000 | G6: Health&Beauty | H6: =SUMIFS(operations[Amount],operations[Category],Expenses9[[#This Row],[Category]],operations[Month],'1'!$B$12) -> -100 | J6: Financial | K6: =SUMIFS(operations[Amount],operations[Category],Table916283236404448[[#This Row],[Category]],operations[Month],'1'!$B$12) -> 105.5 | N6: Expense
A7: Wallet | B7: Gift card | C7: 200 | D7: =SUMIFS(operations[Amount],operations[Bank],raports_9[[#This Row],[Bank]],operations[Product],raports_9[[#This Row],[Product]],operations[Month],$B$12) -> 0 | E7: =raports_9[[#This Row],[Opening balance]]+raports_9[[#This Row],[Operation]] -> 200 | G7: Multimedia | H7: =SUMIFS(operations[Amount],operations[Category],Expenses9[[#This Row],[Category]],operations[Month],'1'!$B$12) -> -150 | J7: Gift | K7: =SUMIFS(operations[Amount],operations[Category],Table916283236404448[[#This Row],[Category]],operations[Month],'1'!$B$12) -> 0 | N7: Expense
A8: Wallet | B8: Money | C8: 30 | D8: =SUMIFS(operations[Amount],operations[Bank],raports_9[[#This Row],[Bank]],operations[Product],raports_9[[#This Row],[Product]],operations[Month],$B$12) -> 0 | E8: =raports_9[[#This Row],[Opening balance]]+raports_9[[#This Row],[Operation]] -> 30 | G8: Total | H8: =SUBTOTAL(109,Expenses9[Total]) -> -4130 | J8: Other incoms | K8: =SUMIFS(operations[Amount],operations[Category],Table916283236404448[[#This Row],[Category]],operations[Month],'1'!$B$12) -> 800 | N8: Expense
A9: Total | C9: =SUBTOTAL(109,raports_9[Opening balance]) -> #REF! | D9: =SUBTOTAL(109,raports_9[Operation]) -> 1751.5 | E9: =SUBTOTAL(109,raports_9[Closing balance]) -> #REF! | J9: Salary | K9: =SUMIFS(operations[Amount],operations[Category],Table916283236404448[[#This Row],[Category]],operations[Month],'1'!$B$12) -> 4500 | N9: Expense
J10: Scholarship | K10: =SUMIFS(operations[Amount],operations[Category],Table916283236404448[[#This Row],[Category]],operations[Month],'1'!$B$12) -> 0 | N10: Expense
J11: Transfer | K11: =SUMIFS(operations[Amount],operations[Category],Table916283236404448[[#This Row],[Category]],operations[Month],'1'!$B$12) -> 0 | N11: Income
A12: Month | B12: {=_xlfn.TEXTAFTER(CELL("filename",A1),"]")} -> 9 | J12: Total | K12: =SUBTOTAL(109,Table916283236404448[Total]) -> 5475.5 | N12: Income
G13: INDIRECT("raport_"&$B$12-1&"[@[Closing balance ]]") | N13: Income
A14: Type | B14: Total | N14: Income
A15: Income | B15: =SUMIFS(operations[Amount],operations[Type],balance_9[[#This Row],[Type]],operations[Month],'1'!$B$12) -> 5655.5 | N15: Income
A16: Expense | B16: =SUMIFS(operations[Amount],operations[Type],balance_9[[#This Row],[Type]],operations[Month],'1'!$B$12) -> -4810 | N16: Income
A17: Transfer | B17: =SUMIFS(operations[Amount],operations[Type],balance_9[[#This Row],[Type]],operations[Month],'1'!$B$12) -> 0 | N17: Transfer
A18: Total | B18: =SUBTOTAL(109,balance_9[Total]) -> 845.5

Sheet 10
A1: Bank | B1: Product | C1: Opening balance | D1: Operation | E1: Closing balance | G1: Category | H1: Total | J1: Category | K1: Total | N1: Type
A2: Millennium | B2: Account | C2: {=INDIRECT("raport_"&$B$12-1&"[@[Closing balance ]]")} -> #REF! | D2: =SUMIFS(operations[Amount],operations[Bank],raports_10[[#This Row],[Bank]],operations[Product],raports_10[[#This Row],[Product]],operations[Month],$B$12) -> 0 | E2: =raports_10[[#This Row],[Opening balance]]+raports_10[[#This Row],[Operation]] -> #REF! | G2: Accomodation | H2: =SUMIFS(operations[Amount],operations[Category],Expenses10[[#This Row],[Category]],operations[Month],'1'!$B$12) -> -2000 | J2: Other expences | N2: Expense
A3: Millennium | B3: Savings account | C3: 10.5 | D3: =SUMIFS(operations[Amount],operations[Bank],raports_10[[#This Row],[Bank]],operations[Product],raports_10[[#This Row],[Product]],operations[Month],$B$12) -> 0 | E3: =raports_10[[#This Row],[Opening balance]]+raports_10[[#This Row],[Operation]] -> 10.5 | G3: Clothing | H3: =SUMIFS(operations[Amount],operations[Category],Expenses10[[#This Row],[Category]],operations[Month],'1'!$B$12) -> -80 | J3: Studies | K3: =SUMIFS(operations[Amount],operations[Category],Table91628323640444852[[#This Row],[Category]],operations[Month],'1'!$B$12) -> -100 | N3: Expense
A4: Santander | B4: Account | C4: 600 | D4: =SUMIFS(operations[Amount],operations[Bank],raports_10[[#This Row],[Bank]],operations[Product],raports_10[[#This Row],[Product]],operations[Month],$B$12) -> 1690 | E4: =raports_10[[#This Row],[Opening balance]]+raports_10[[#This Row],[Operation]] -> 2290 | G4: Entertainment | H4: =SUMIFS(operations[Amount],operations[Category],Expenses10[[#This Row],[Category]],operations[Month],'1'!$B$12) -> -85 | J4: Transportation | K4: =SUMIFS(operations[Amount],operations[Category],Table91628323640444852[[#This Row],[Category]],operations[Month],'1'!$B$12) -> -80 | N4: Expense
